<?xml version="1.0" encoding="utf-8"?>
<!-- This URDF was automatically created by SolidWorks to URDF Exporter! Originally created by Stephen Brawner (brawner@gmail.com) 
     Commit Version: 1.6.0-4-g7f85cfe  Build Version: 1.6.7995.38578
     For more information, please see http://wiki.ros.org/sw_urdf_exporter -->
<robot
  name="LZ01_Lite_V3">
  <!-- <mujoco>
    <compiler meshdir="../meshes/" balanceinertia="true" discardvisual="false" fusestatic="false"/>
  </mujoco>
  <link name="world"></link>
  <joint name="floating_base_joint" type="floating">
    <parent link="world" />
    <child link="pelvis_link" />
  </joint> -->
  <link
    name="pelvis_link">
    <inertial>
      <origin
        xyz="-5.8492E-06 8.4885E-07 -0.024029"
        rpy="0 0 0" />
      <mass
        value="2.3981" />
      <inertia
        ixx="0.002725"
        ixy="-3.7963E-06"
        ixz="-2.2293E-06"
        iyy="0.0024552"
        iyz="5.1663E-08"
        izz="0.002601" />
    </inertial>
    <visual>
      <origin
        xyz="0 0 0"
        rpy="0 0 0" />
      <geometry>
        <mesh
          filename="package://LZ01_Lite_V3/meshes/pelvis_link.STL" />
      </geometry>
      <material
        name="">
        <color
          rgba="0.8902 0.8902 0.91373 1" />
      </material>
    </visual>
    <collision>
      <origin
        xyz="0 0 0"
        rpy="0 0 0" />
      <geometry>
        <mesh
          filename="package://LZ01_Lite_V3/meshes/pelvis_link.STL" />
      </geometry>
    </collision>
  </link>
  <link
    name="left_hip_pitch_link">
    <inertial>
      <origin
        xyz="-0.0027623 0.04103 -0.052472"
        rpy="0 0 0" />
      <mass
        value="1.0143" />
      <inertia
        ixx="0.0010959"
        ixy="8.6224E-08"
        ixz="-4.6457E-08"
        iyy="0.00089304"
        iyz="3.0866E-05"
        izz="0.00080591" />
    </inertial>
    <visual>
      <origin
        xyz="0 0 0"
        rpy="0 0 0" />
      <geometry>
        <mesh
          filename="package://LZ01_Lite_V3/meshes/left_hip_pitch_link.STL" />
      </geometry>
      <material
        name="">
        <color
          rgba="0.8902 0.8902 0.91373 1" />
      </material>
    </visual>
    <collision>
      <origin
        xyz="0 0 0"
        rpy="0 0 0" />
      <geometry>
        <mesh
          filename="package://LZ01_Lite_V3/meshes/left_hip_pitch_link.STL" />
      </geometry>
    </collision>
  </link>
  <joint
    name="left_hip_pitch_joint"
    type="revolute">
    <origin
      xyz="0 0.075171 -0.0434"
      rpy="-0.5236 0 0" />
    <parent
      link="pelvis_link" />
    <child
      link="left_hip_pitch_link" />
    <axis
      xyz="0 1 0" />
    <limit
      lower="-2.181"
      upper="2.181"
      effort="80"
      velocity="10.4" />
  </joint>
  <link
    name="left_hip_roll_link">
    <inertial>
      <origin
        xyz="0.01872 0.00068656 -0.037436"
        rpy="0 0 0" />
      <mass
        value="0.18644" />
      <inertia
        ixx="0.00023195"
        ixy="-8.7615E-07"
        ixz="-2.9039E-05"
        iyy="0.00016816"
        iyz="-3.4449E-06"
        izz="0.00013468" />
    </inertial>
    <visual>
      <origin
        xyz="0 0 0"
        rpy="0 0 0" />
      <geometry>
        <mesh
          filename="package://LZ01_Lite_V3/meshes/left_hip_roll_link.STL" />
      </geometry>
      <material
        name="">
        <color
          rgba="0.8902 0.8902 0.91373 1" />
      </material>
    </visual>
    <collision>
      <origin
        xyz="0 0 0"
        rpy="0 0 0" />
      <geometry>
        <mesh
          filename="package://LZ01_Lite_V3/meshes/left_hip_roll_link.STL" />
      </geometry>
    </collision>
  </link>
  <joint
    name="left_hip_roll_joint"
    type="revolute">
    <origin
      xyz="0 0.045 -0.06"
      rpy="0.5236 0 0" />
    <parent
      link="left_hip_pitch_link" />
    <child
      link="left_hip_roll_link" />
    <axis
      xyz="1 0 0" />
    <limit
      lower="-0.523"
      upper="1.57"
      effort="80"
      velocity="10.4" />
  </joint>
  <link
    name="left_hip_yaw_link">
    <inertial>
      <origin
        xyz="-0.009409 0.0023219 -0.099988"
        rpy="0 0 0" />
      <mass
        value="1.6983" />
      <inertia
        ixx="0.0014193"
        ixy="-2.799E-06"
        ixz="5.5512E-06"
        iyy="0.0017864"
        iyz="-5.6544E-06"
        izz="0.0013354" />
    </inertial>
    <visual>
      <origin
        xyz="0 0 0"
        rpy="0 0 0" />
      <geometry>
        <mesh
          filename="package://LZ01_Lite_V3/meshes/left_hip_yaw_link.STL" />
      </geometry>
      <material
        name="">
        <color
          rgba="0.8902 0.8902 0.91373 1" />
      </material>
    </visual>
    <collision>
      <origin
        xyz="0 0 0"
        rpy="0 0 0" />
      <geometry>
        <mesh
          filename="package://LZ01_Lite_V3/meshes/left_hip_yaw_link.STL" />
      </geometry>
    </collision>
  </link>
  <joint
    name="left_hip_yaw_joint"
    type="revolute">
    <origin
      xyz="0 0 -0.065"
      rpy="0 0 0" />
    <parent
      link="left_hip_roll_link" />
    <child
      link="left_hip_yaw_link" />
    <axis
      xyz="0 0 1" />
    <limit
      lower="-1.745"
      upper="1.745"
      effort="36"
      velocity="10.4" />
  </joint>
  <link
    name="left_knee_link">
    <inertial>
      <origin
        xyz="0.012433 -0.0026256 -0.13804"
        rpy="0 0 0" />
      <mass
        value="1.6142" />
      <inertia
        ixx="0.0040513"
        ixy="-1.5104E-05"
        ixz="6.8565E-05"
        iyy="0.0038689"
        iyz="0.00027551"
        izz="0.00079954" />
    </inertial>
    <visual>
      <origin
        xyz="0 0 0"
        rpy="0 0 0" />
      <geometry>
        <mesh
          filename="package://LZ01_Lite_V3/meshes/left_knee_link.STL" />
      </geometry>
      <material
        name="">
        <color
          rgba="0.8902 0.8902 0.91373 1" />
      </material>
    </visual>
    <collision>
      <origin
        xyz="0 0 0"
        rpy="0 0 0" />
      <geometry>
        <mesh
          filename="package://LZ01_Lite_V3/meshes/left_knee_link.STL" />
      </geometry>
    </collision>
  </link>
  <joint
    name="left_knee_joint"
    type="revolute">
    <origin
      xyz="-0.017 0 -0.145"
      rpy="0 0 0" />
    <parent
      link="left_hip_yaw_link" />
    <child
      link="left_knee_link" />
    <axis
      xyz="0 1 0" />
    <limit
      lower="-0.087"
      upper="2.443"
      effort="80"
      velocity="10.4" />
  </joint>
  <link
    name="left_ankle_pitch_link">
    <inertial>
      <origin
        xyz="0.00032738 7.8877E-12 -0.018502"
        rpy="0 0 0" />
      <mass
        value="0.1573" />
      <inertia
        ixx="3.1707E-05"
        ixy="2.0522E-14"
        ixz="1.3069E-06"
        iyy="5.5127E-05"
        iyz="6.3147E-15"
        izz="2.8717E-05" />
    </inertial>
    <visual>
      <origin
        xyz="0 0 0"
        rpy="0 0 0" />
      <geometry>
        <mesh
          filename="package://LZ01_Lite_V3/meshes/left_ankle_pitch_link.STL" />
      </geometry>
      <material
        name="">
        <color
          rgba="0.64706 0.61961 0.58824 1" />
      </material>
    </visual>
    <collision>
      <origin
        xyz="0 0 0"
        rpy="0 0 0" />
      <geometry>
        <mesh
          filename="package://LZ01_Lite_V3/meshes/left_ankle_pitch_link.STL" />
      </geometry>
    </collision>
  </link>
  <joint
    name="left_ankle_pitch_joint"
    type="revolute">
    <origin
      xyz="0.017 0 -0.27"
      rpy="0 0 0" />
    <parent
      link="left_knee_link" />
    <child
      link="left_ankle_pitch_link" />
    <axis
      xyz="0 1 0" />
    <limit
      lower="-1.047"
      upper="0.523"
      effort="36"
      velocity="10.4" />
  </joint>
  <link
    name="left_ankle_roll_link">
    <inertial>
      <origin
        xyz="0.030665 -0.0013065 -0.013853"
        rpy="0 0 0" />
      <mass
        value="0.57338" />
      <inertia
        ixx="0.00030248"
        ixy="1.7377E-06"
        ixz="8.0304E-06"
        iyy="0.0012435"
        iyz="-7.171E-08"
        izz="0.0014857" />
    </inertial>
    <visual>
      <origin
        xyz="0 0 0"
        rpy="0 0 0" />
      <geometry>
        <mesh
          filename="package://LZ01_Lite_V3/meshes/left_ankle_roll_link.STL" />
      </geometry>
      <material
        name="">
        <color
          rgba="0.8902 0.8902 0.91373 1" />
      </material>
    </visual>
    <collision>
      <origin
        xyz="0 0 0"
        rpy="0 0 0" />
      <geometry>
        <mesh
          filename="package://LZ01_Lite_V3/meshes/left_ankle_roll_link.STL" />
      </geometry>
    </collision>
  </link>
  <joint
    name="left_ankle_roll_joint"
    type="revolute">
    <origin
      xyz="0 0 -0.03"
      rpy="0 0 0" />
    <parent
      link="left_ankle_pitch_link" />
    <child
      link="left_ankle_roll_link" />
    <axis
      xyz="1 0 0" />
    <limit
      lower="-0.261"
      upper="0.261"
      effort="36"
      velocity="10.4" />
  </joint>
  <link
    name="right_hip_pitch_link">
    <inertial>
      <origin
        xyz="-0.0027627 -0.041034 -0.05247"
        rpy="0 0 0" />
      <mass
        value="1.0143" />
      <inertia
        ixx="0.0010959"
        ixy="1.5224E-08"
        ixz="-8.7688E-08"
        iyy="0.00089308"
        iyz="-3.0842E-05"
        izz="0.00080587" />
    </inertial>
    <visual>
      <origin
        xyz="0 0 0"
        rpy="0 0 0" />
      <geometry>
        <mesh
          filename="package://LZ01_Lite_V3/meshes/right_hip_pitch_link.STL" />
      </geometry>
      <material
        name="">
        <color
          rgba="0.8902 0.8902 0.91373 1" />
      </material>
    </visual>
    <collision>
      <origin
        xyz="0 0 0"
        rpy="0 0 0" />
      <geometry>
        <mesh
          filename="package://LZ01_Lite_V3/meshes/right_hip_pitch_link.STL" />
      </geometry>
    </collision>
  </link>
  <joint
    name="right_hip_pitch_joint"
    type="revolute">
    <origin
      xyz="0 -0.075171 -0.0434"
      rpy="0.5236 0 0" />
    <parent
      link="pelvis_link" />
    <child
      link="right_hip_pitch_link" />
    <axis
      xyz="0 1 0" />
    <limit
      lower="-2.181"
      upper="2.181"
      effort="80"
      velocity="10.4" />
  </joint>
  <link
    name="right_hip_roll_link">
    <inertial>
      <origin
        xyz="0.018712 -0.00068881 -0.037438"
        rpy="0 0 0" />
      <mass
        value="0.18641" />
      <inertia
        ixx="0.00023192"
        ixy="8.7387E-07"
        ixz="-2.9031E-05"
        iyy="0.00016814"
        iyz="3.4565E-06"
        izz="0.00013464" />
    </inertial>
    <visual>
      <origin
        xyz="0 0 0"
        rpy="0 0 0" />
      <geometry>
        <mesh
          filename="package://LZ01_Lite_V3/meshes/right_hip_roll_link.STL" />
      </geometry>
      <material
        name="">
        <color
          rgba="1 1 1 1" />
      </material>
    </visual>
    <collision>
      <origin
        xyz="0 0 0"
        rpy="0 0 0" />
      <geometry>
        <mesh
          filename="package://LZ01_Lite_V3/meshes/right_hip_roll_link.STL" />
      </geometry>
    </collision>
  </link>
  <joint
    name="right_hip_roll_joint"
    type="revolute">
    <origin
      xyz="0 -0.045 -0.06"
      rpy="-0.5236 0 0" />
    <parent
      link="right_hip_pitch_link" />
    <child
      link="right_hip_roll_link" />
    <axis
      xyz="1 0 0" />
    <limit
      lower="-1.57"
      upper="0.523"
      effort="80"
      velocity="10.4" />
  </joint>
  <link
    name="right_hip_yaw_link">
    <inertial>
      <origin
        xyz="-0.0094067 -0.0023217 -0.099989"
        rpy="0 0 0" />
      <mass
        value="1.6983" />
      <inertia
        ixx="0.0014193"
        ixy="2.6832E-06"
        ixz="5.5375E-06"
        iyy="0.0017864"
        iyz="5.6891E-06"
        izz="0.0013355" />
    </inertial>
    <visual>
      <origin
        xyz="0 0 0"
        rpy="0 0 0" />
      <geometry>
        <mesh
          filename="package://LZ01_Lite_V3/meshes/right_hip_yaw_link.STL" />
      </geometry>
      <material
        name="">
        <color
          rgba="0.8902 0.8902 0.91373 1" />
      </material>
    </visual>
    <collision>
      <origin
        xyz="0 0 0"
        rpy="0 0 0" />
      <geometry>
        <mesh
          filename="package://LZ01_Lite_V3/meshes/right_hip_yaw_link.STL" />
      </geometry>
    </collision>
  </link>
  <joint
    name="right_hip_yaw_joint"
    type="revolute">
    <origin
      xyz="0 0 -0.065"
      rpy="0 0 0" />
    <parent
      link="right_hip_roll_link" />
    <child
      link="right_hip_yaw_link" />
    <axis
      xyz="0 0 1" />
    <limit
      lower="-1.745"
      upper="1.745"
      effort="36"
      velocity="10.4" />
  </joint>
  <link
    name="right_knee_link">
    <inertial>
      <origin
        xyz="0.012426 0.0026243 -0.13804"
        rpy="0 0 0" />
      <mass
        value="1.6142" />
      <inertia
        ixx="0.0040512"
        ixy="1.5096E-05"
        ixz="6.9521E-05"
        iyy="0.0038689"
        iyz="-0.0002755"
        izz="0.00079951" />
    </inertial>
    <visual>
      <origin
        xyz="0 0 0"
        rpy="0 0 0" />
      <geometry>
        <mesh
          filename="package://LZ01_Lite_V3/meshes/right_knee_link.STL" />
      </geometry>
      <material
        name="">
        <color
          rgba="0.8902 0.8902 0.91373 1" />
      </material>
    </visual>
    <collision>
      <origin
        xyz="0 0 0"
        rpy="0 0 0" />
      <geometry>
        <mesh
          filename="package://LZ01_Lite_V3/meshes/right_knee_link.STL" />
      </geometry>
    </collision>
  </link>
  <joint
    name="right_knee_joint"
    type="revolute">
    <origin
      xyz="-0.017 0 -0.145"
      rpy="0 0 0" />
    <parent
      link="right_hip_yaw_link" />
    <child
      link="right_knee_link" />
    <axis
      xyz="0 1 0" />
    <limit
      lower="-0.087"
      upper="2.443"
      effort="80"
      velocity="10.4" />
  </joint>
  <link
    name="right_ankle_pitch_link">
    <inertial>
      <origin
        xyz="0.00032738 9.5676E-12 -0.018502"
        rpy="0 0 0" />
      <mass
        value="0.1573" />
      <inertia
        ixx="3.1707E-05"
        ixy="2.0522E-14"
        ixz="1.3069E-06"
        iyy="5.5127E-05"
        iyz="6.3147E-15"
        izz="2.8717E-05" />
    </inertial>
    <visual>
      <origin
        xyz="0 0 0"
        rpy="0 0 0" />
      <geometry>
        <mesh
          filename="package://LZ01_Lite_V3/meshes/right_ankle_pitch_link.STL" />
      </geometry>
      <material
        name="">
        <color
          rgba="0.64706 0.61961 0.58824 1" />
      </material>
    </visual>
    <collision>
      <origin
        xyz="0 0 0"
        rpy="0 0 0" />
      <geometry>
        <mesh
          filename="package://LZ01_Lite_V3/meshes/right_ankle_pitch_link.STL" />
      </geometry>
    </collision>
  </link>
  <joint
    name="right_ankle_pitch_joint"
    type="revolute">
    <origin
      xyz="0.017 0 -0.27"
      rpy="0 0 0" />
    <parent
      link="right_knee_link" />
    <child
      link="right_ankle_pitch_link" />
    <axis
      xyz="0 1 0" />
    <limit
      lower="-1.047"
      upper="0.523"
      effort="36"
      velocity="10.4" />
  </joint>
  <link
    name="right_ankle_roll_link">
    <inertial>
      <origin
        xyz="0.030658 0.0013121 -0.013852"
        rpy="0 0 0" />
      <mass
        value="0.5735" />
      <inertia
        ixx="0.00030256"
        ixy="-1.6701E-06"
        ixz="8.0031E-06"
        iyy="0.0012437"
        iyz="1.024E-07"
        izz="0.001486" />
    </inertial>
    <visual>
      <origin
        xyz="0 0 0"
        rpy="0 0 0" />
      <geometry>
        <mesh
          filename="package://LZ01_Lite_V3/meshes/right_ankle_roll_link.STL" />
      </geometry>
      <material
        name="">
        <color
          rgba="0.8902 0.8902 0.91373 1" />
      </material>
    </visual>
    <collision>
      <origin
        xyz="0 0 0"
        rpy="0 0 0" />
      <geometry>
        <mesh
          filename="package://LZ01_Lite_V3/meshes/right_ankle_roll_link.STL" />
      </geometry>
    </collision>
  </link>
  <joint
    name="right_ankle_roll_joint"
    type="revolute">
    <origin
      xyz="0 0 -0.03"
      rpy="0 0 0" />
    <parent
      link="right_ankle_pitch_link" />
    <child
      link="right_ankle_roll_link" />
    <axis
      xyz="1 0 0" />
    <limit
      lower="-0.261"
      upper="0.261"
      effort="36"
      velocity="10.4" />
  </joint>
  <link
    name="torso_yaw_link">
    <inertial>
      <origin
        xyz="-0.0002144 -0.00014585 0.16212"
        rpy="0 0 0" />
      <mass
        value="5.7494" />
      <inertia
        ixx="0.01291"
        ixy="-8.8395E-05"
        ixz="0.00012217"
        iyy="0.0079656"
        iyz="-1.791E-05"
        izz="0.011799" />
    </inertial>
    <visual>
      <origin
        xyz="0 0 0"
        rpy="0 0 0" />
      <geometry>
        <mesh
          filename="package://LZ01_Lite_V3/meshes/torso_yaw_link.STL" />
      </geometry>
      <material
        name="">
        <color
          rgba="0.8902 0.8902 0.91373 1" />
      </material>
    </visual>
    <collision>
      <origin
        xyz="0 0 0"
        rpy="0 0 0" />
      <geometry>
        <mesh
          filename="package://LZ01_Lite_V3/meshes/torso_yaw_link.STL" />
      </geometry>
    </collision>
  </link>
  <joint
    name="torso_yaw_joint"
    type="revolute">
    <origin
      xyz="0 0 0.02"
      rpy="0 0 0" />
    <parent
      link="pelvis_link" />
    <child
      link="torso_yaw_link" />
    <axis
      xyz="0 0 1" />
    <limit
      lower="-1.832"
      upper="1.832"
      effort="36"
      velocity="10.4" />
  </joint>
  <link
    name="right_shoulder_pitch_link">
    <inertial>
      <origin
        xyz="0.00021514 -0.035932 -1.2302E-05"
        rpy="0 0 0" />
      <mass
        value="0.51326" />
      <inertia
        ixx="0.00022475"
        ixy="-4.9422E-11"
        ixz="7.9359E-10"
        iyy="0.0002387"
        iyz="6.6986E-08"
        izz="0.00024526" />
    </inertial>
    <visual>
      <origin
        xyz="0 0 0"
        rpy="0 0 0" />
      <geometry>
        <mesh
          filename="package://LZ01_Lite_V3/meshes/right_shoulder_pitch_link.STL" />
      </geometry>
      <material
        name="">
        <color
          rgba="0.8902 0.8902 0.91373 1" />
      </material>
    </visual>
    <collision>
      <origin
        xyz="0 0 0"
        rpy="0 0 0" />
      <geometry>
        <mesh
          filename="package://LZ01_Lite_V3/meshes/right_shoulder_pitch_link.STL" />
      </geometry>
    </collision>
  </link>
  <joint
    name="right_shoulder_pitch_joint"
    type="revolute">
    <origin
      xyz="0 -0.1115 0.216"
      rpy="0 0 0" />
    <parent
      link="torso_yaw_link" />
    <child
      link="right_shoulder_pitch_link" />
    <axis
      xyz="0 1 0" />
    <limit
      lower="-3.665"
      upper="1.57"
      effort="36"
      velocity="10.4" />
  </joint>
  <link
    name="right_shoulder_roll_link">
    <inertial>
      <origin
        xyz="-0.00020711 3.3213E-08 -0.066445"
        rpy="0 0 0" />
      <mass
        value="0.60617" />
      <inertia
        ixx="0.00043215"
        ixy="-6.7216E-07"
        ixz="-1.6157E-06"
        iyy="0.00039874"
        iyz="1.221E-09"
        izz="0.00030499" />
    </inertial>
    <visual>
      <origin
        xyz="0 0 0"
        rpy="0 0 0" />
      <geometry>
        <mesh
          filename="package://LZ01_Lite_V3/meshes/right_shoulder_roll_link.STL" />
      </geometry>
      <material
        name="">
        <color
          rgba="0.8902 0.8902 0.91373 1" />
      </material>
    </visual>
    <collision>
      <origin
        xyz="0 0 0"
        rpy="0 0 0" />
      <geometry>
        <mesh
          filename="package://LZ01_Lite_V3/meshes/right_shoulder_roll_link.STL" />
      </geometry>
    </collision>
  </link>
  <joint
    name="right_shoulder_roll_joint"
    type="revolute">
    <origin
      xyz="0 -0.039 0"
      rpy="0 0 0" />
    <parent
      link="right_shoulder_pitch_link" />
    <child
      link="right_shoulder_roll_link" />
    <axis
      xyz="1 0 0" />
    <limit
      lower="-3.228"
      upper="0.087"
      effort="36"
      velocity="10.4" />
  </joint>
  <link
    name="right_shoulder_yaw_link">
    <inertial>
      <origin
        xyz="0.0077083 -0.00032649 -0.051345"
        rpy="0 0 0" />
      <mass
        value="0.61072" />
      <inertia
        ixx="0.00039289"
        ixy="-1.9638E-07"
        ixz="1.7003E-05"
        iyy="0.00037343"
        iyz="2.2324E-07"
        izz="0.0002798" />
    </inertial>
    <visual>
      <origin
        xyz="0 0 0"
        rpy="0 0 0" />
      <geometry>
        <mesh
          filename="package://LZ01_Lite_V3/meshes/right_shoulder_yaw_link.STL" />
      </geometry>
      <material
        name="">
        <color
          rgba="0.8902 0.8902 0.91373 1" />
      </material>
    </visual>
    <collision>
      <origin
        xyz="0 0 0"
        rpy="0 0 0" />
      <geometry>
        <mesh
          filename="package://LZ01_Lite_V3/meshes/right_shoulder_yaw_link.STL" />
      </geometry>
    </collision>
  </link>
  <joint
    name="right_shoulder_yaw_joint"
    type="revolute">
    <origin
      xyz="0 0 -0.109"
      rpy="0 0 0" />
    <parent
      link="right_shoulder_roll_link" />
    <child
      link="right_shoulder_yaw_link" />
    <axis
      xyz="0 0 1" />
    <limit
      lower="-2.617"
      upper="2.617"
      effort="36"
      velocity="10.4" />
  </joint>
  <link
    name="right_elbow_link">
    <inertial>
      <origin
        xyz="-0.0094205 0.00047447 -0.093259"
        rpy="0 0 0" />
      <mass
        value="0.41439" />
      <inertia
        ixx="0.0008863"
        ixy="-1.2768E-07"
        ixz="-6.3265E-06"
        iyy="0.00093469"
        iyz="-1.7282E-06"
        izz="0.00019625" />
    </inertial>
    <visual>
      <origin
        xyz="0 0 0"
        rpy="0 0 0" />
      <geometry>
        <mesh
          filename="package://LZ01_Lite_V3/meshes/right_elbow_link.STL" />
      </geometry>
      <material
        name="">
        <color
          rgba="0.8902 0.8902 0.91373 1" />
      </material>
    </visual>
    <collision>
      <origin
        xyz="0 0 0"
        rpy="0 0 0" />
      <geometry>
        <mesh
          filename="package://LZ01_Lite_V3/meshes/right_elbow_link.STL" />
      </geometry>
    </collision>
  </link>
  <joint
    name="right_elbow_joint"
    type="revolute">
    <origin
      xyz="0.0095 0 -0.059"
      rpy="0 0 0" />
    <parent
      link="right_shoulder_yaw_link" />
    <child
      link="right_elbow_link" />
    <axis
      xyz="0 1 0" />
    <limit
      lower="-2.356"
      upper="0.087"
      effort="36"
      velocity="10.4" />
  </joint>
  <link
    name="left_shoulder_pitch_link">
    <inertial>
      <origin
        xyz="0.00021514 0.035932 1.2302E-05"
        rpy="0 0 0" />
      <mass
        value="0.51326" />
      <inertia
        ixx="0.00022475"
        ixy="4.9422E-11"
        ixz="-7.9359E-10"
        iyy="0.0002387"
        iyz="6.6986E-08"
        izz="0.00024526" />
    </inertial>
    <visual>
      <origin
        xyz="0 0 0"
        rpy="0 0 0" />
      <geometry>
        <mesh
          filename="package://LZ01_Lite_V3/meshes/left_shoulder_pitch_link.STL" />
      </geometry>
      <material
        name="">
        <color
          rgba="0.8902 0.8902 0.91373 1" />
      </material>
    </visual>
    <collision>
      <origin
        xyz="0 0 0"
        rpy="0 0 0" />
      <geometry>
        <mesh
          filename="package://LZ01_Lite_V3/meshes/left_shoulder_pitch_link.STL" />
      </geometry>
    </collision>
  </link>
  <joint
    name="left_shoulder_pitch_joint"
    type="revolute">
    <origin
      xyz="0 0.1115 0.216"
      rpy="0 0 0" />
    <parent
      link="torso_yaw_link" />
    <child
      link="left_shoulder_pitch_link" />
    <axis
      xyz="0 1 0" />
    <limit
      lower="-3.665"
      upper="1.57"
      effort="36"
      velocity="10.4" />
  </joint>
  <link
    name="left_shoulder_roll_link">
    <inertial>
      <origin
        xyz="-0.00020711 3.323E-08 -0.066445"
        rpy="0 0 0" />
      <mass
        value="0.60617" />
      <inertia
        ixx="0.00043215"
        ixy="-6.7224E-07"
        ixz="-1.616E-06"
        iyy="0.00039874"
        iyz="1.3558E-09"
        izz="0.00030499" />
    </inertial>
    <visual>
      <origin
        xyz="0 0 0"
        rpy="0 0 0" />
      <geometry>
        <mesh
          filename="package://LZ01_Lite_V3/meshes/left_shoulder_roll_link.STL" />
      </geometry>
      <material
        name="">
        <color
          rgba="0.8902 0.8902 0.91373 1" />
      </material>
    </visual>
    <collision>
      <origin
        xyz="0 0 0"
        rpy="0 0 0" />
      <geometry>
        <mesh
          filename="package://LZ01_Lite_V3/meshes/left_shoulder_roll_link.STL" />
      </geometry>
    </collision>
  </link>
  <joint
    name="left_shoulder_roll_joint"
    type="revolute">
    <origin
      xyz="0 0.039 0"
      rpy="0 0 0" />
    <parent
      link="left_shoulder_pitch_link" />
    <child
      link="left_shoulder_roll_link" />
    <axis
      xyz="1 0 0" />
    <limit
      lower="-0.087"
      upper="3.228"
      effort="36"
      velocity="10.4" />
  </joint>
  <link
    name="left_shoulder_yaw_link">
    <inertial>
      <origin
        xyz="0.0077083 -0.00032649 -0.051345"
        rpy="0 0 0" />
      <mass
        value="0.61072" />
      <inertia
        ixx="0.00039289"
        ixy="-1.9638E-07"
        ixz="1.7003E-05"
        iyy="0.00037343"
        iyz="2.2324E-07"
        izz="0.0002798" />
    </inertial>
    <visual>
      <origin
        xyz="0 0 0"
        rpy="0 0 0" />
      <geometry>
        <mesh
          filename="package://LZ01_Lite_V3/meshes/left_shoulder_yaw_link.STL" />
      </geometry>
      <material
        name="">
        <color
          rgba="0.8902 0.8902 0.91373 1" />
      </material>
    </visual>
    <collision>
      <origin
        xyz="0 0 0"
        rpy="0 0 0" />
      <geometry>
        <mesh
          filename="package://LZ01_Lite_V3/meshes/left_shoulder_yaw_link.STL" />
      </geometry>
    </collision>
  </link>
  <joint
    name="left_shoulder_yaw_joint"
    type="revolute">
    <origin
      xyz="0 0 -0.109"
      rpy="0 0 0" />
    <parent
      link="left_shoulder_roll_link" />
    <child
      link="left_shoulder_yaw_link" />
    <axis
      xyz="0 0 1" />
    <limit
      lower="-2.617"
      upper="2.617"
      effort="36"
      velocity="10.4" />
  </joint>
  <link
    name="left_elbow_link">
    <inertial>
      <origin
        xyz="-0.0094205 0.00047447 -0.093259"
        rpy="0 0 0" />
      <mass
        value="0.41439" />
      <inertia
        ixx="0.0008863"
        ixy="-1.2768E-07"
        ixz="-6.3265E-06"
        iyy="0.00093469"
        iyz="-1.7282E-06"
        izz="0.00019625" />
    </inertial>
    <visual>
      <origin
        xyz="0 0 0"
        rpy="0 0 0" />
      <geometry>
        <mesh
          filename="package://LZ01_Lite_V3/meshes/left_elbow_link.STL" />
      </geometry>
      <material
        name="">
        <color
          rgba="0.8902 0.8902 0.91373 1" />
      </material>
    </visual>
    <collision>
      <origin
        xyz="0 0 0"
        rpy="0 0 0" />
      <geometry>
        <mesh
          filename="package://LZ01_Lite_V3/meshes/left_elbow_link.STL" />
      </geometry>
    </collision>
  </link>
  <joint
    name="left_elbow_joint"
    type="revolute">
    <origin
      xyz="0.0095 0 -0.059"
      rpy="0 0 0" />
    <parent
      link="left_shoulder_yaw_link" />
    <child
      link="left_elbow_link" />
    <axis
      xyz="0 1 0" />
    <limit
      lower="-2.356"
      upper="0.087"
      effort="36"
      velocity="10.4" />
  </joint>
</robot>