<?xml version="1.0" encoding="utf-8"?>
<!-- This URDF was automatically created by SolidWorks to URDF Exporter! Originally created by Stephen Brawner (brawner@gmail.com) 
     Commit Version: 1.6.0-1-g15f4949  Build Version: 1.6.7594.29634
     For more information, please see http://wiki.ros.org/sw_urdf_exporter -->
<robot
  name="A7_V2.0">
  <link
    name="base_link">
    <inertial>
      <origin
        xyz="2.9476E-06 0.00059109 0.035945"
        rpy="0 0 0" />
      <mass
        value="1.3934" />
      <inertia
        ixx="0.0010366"
        ixy="-4.6571E-06"
        ixz="-1.0004E-09"
        iyy="0.00092144"
        iyz="-1.646E-06"
        izz="0.0015392" />
    </inertial>
    <visual>
      <origin
        xyz="0 0 0"
        rpy="0 0 0" />
      <geometry>
        <mesh
          filename="meshes/base_link.STL" />
      </geometry>
      <material
        name="">
        <color
          rgba="0.75294 0.75294 0.75294 1" />
      </material>
    </visual>
    <collision>
      <origin
        xyz="0 0 0"
        rpy="0 0 0" />
      <geometry>
        <mesh
          filename="meshes/base_link.STL" />
      </geometry>
    </collision>
  </link>
  <link
    name="A1_Link">
    <inertial>
      <origin
        xyz="0.0026942 -0.00010595 0.053498"
        rpy="0 0 0" />
      <mass
        value="1.3809" />
      <inertia
        ixx="0.0011393"
        ixy="9.944E-09"
        ixz="-2.2259E-06"
        iyy="0.00068756"
        iyz="-1.0591E-06"
        izz="0.00065344" />
    </inertial>
    <visual>
      <origin
        xyz="0 0 0"
        rpy="0 0 0" />
      <geometry>
        <mesh
          filename="meshes/A1_Link.STL" />
      </geometry>
      <material
        name="">
        <color
          rgba="0.75294 0.75294 0.75294 1" />
      </material>
    </visual>
    <collision>
      <origin
        xyz="0 0 0"
        rpy="0 0 0" />
      <geometry>
        <mesh
          filename="meshes/A1_Link.STL" />
      </geometry>
    </collision>
  </link>
  <joint
    name="A1_Joint"
    type="revolute">
    <origin
      xyz="0 0 0.0645"
      rpy="0 0 0" />
    <parent
      link="base_link" />
    <child
      link="A1_Link" />
    <axis
      xyz="0 0 1" />
    <limit
      lower="-2.91"
      upper="2.91"
      effort="80"
      velocity="10.47" />
  </joint>
  <link
    name="A2_Link">
    <inertial>
      <origin
        xyz="0.0016184 -8.1895E-06 0.079574"
        rpy="0 0 0" />
      <mass
        value="1.1421" />
      <inertia
        ixx="0.00099926"
        ixy="-4.3839E-06"
        ixz="1.3411E-06"
        iyy="0.0009296"
        iyz="2.7915E-07"
        izz="0.00049087" />
    </inertial>
    <visual>
      <origin
        xyz="0 0 0"
        rpy="0 0 0" />
      <geometry>
        <mesh
          filename="meshes/A2_Link.STL" />
      </geometry>
      <material
        name="">
        <color
          rgba="0.75294 0.75294 0.75294 1" />
      </material>
    </visual>
    <collision>
      <origin
        xyz="0 0 0"
        rpy="0 0 0" />
      <geometry>
        <mesh
          filename="meshes/A2_Link.STL" />
      </geometry>
    </collision>
  </link>
  <joint
    name="A2_Joint"
    type="revolute">
    <origin
      xyz="0 0 0.058"
      rpy="0 0 0" />
    <parent
      link="A1_Link" />
    <child
      link="A2_Link" />
    <axis
      xyz="1 0 0" />
    <limit
      lower="-1.64"
      upper="1.64"
      effort="80"
      velocity="10.47" />
  </joint>
  <link
    name="A3_Link">
    <inertial>
      <origin
        xyz="0.00018108 -0.0012493 0.12855"
        rpy="0 0 0" />
      <mass
        value="1.2798" />
      <inertia
        ixx="0.001581"
        ixy="-7.7193E-07"
        ixz="8.6942E-07"
        iyy="0.0016315"
        iyz="-2.4154E-06"
        izz="0.00034415" />
    </inertial>
    <visual>
      <origin
        xyz="0 0 0"
        rpy="0 0 0" />
      <geometry>
        <mesh
          filename="meshes/A3_Link.STL" />
      </geometry>
      <material
        name="">
        <color
          rgba="0.75294 0.75294 0.75294 1" />
      </material>
    </visual>
    <collision>
      <origin
        xyz="0 0 0"
        rpy="0 0 0" />
      <geometry>
        <mesh
          filename="meshes/A3_Link.STL" />
      </geometry>
    </collision>
  </link>
  <joint
    name="A3_Joint"
    type="revolute">
    <origin
      xyz="-2.5027E-05 0 0.123"
      rpy="0 0 0" />
    <parent
      link="A2_Link" />
    <child
      link="A3_Link" />
    <axis
      xyz="0 0 1" />
    <limit
      lower="-2.69"
      upper="2.69"
      effort="36"
      velocity="9.1" />
  </joint>
  <link
    name="A4_Link">
    <inertial>
      <origin
        xyz="-4.5339E-06 -0.00098093 0.084098"
        rpy="0 0 0" />
      <mass
        value="0.94109" />
      <inertia
        ixx="0.00050831"
        ixy="4.1242E-06"
        ixz="1.6031E-07"
        iyy="0.00052415"
        iyz="-3.4576E-07"
        izz="0.00033405" />
    </inertial>
    <visual>
      <origin
        xyz="0 0 0"
        rpy="0 0 0" />
      <geometry>
        <mesh
          filename="meshes/A4_Link.STL" />
      </geometry>
      <material
        name="">
        <color
          rgba="0.75294 0.75294 0.75294 1" />
      </material>
    </visual>
    <collision>
      <origin
        xyz="0 0 0"
        rpy="0 0 0" />
      <geometry>
        <mesh
          filename="meshes/A4_Link.STL" />
      </geometry>
    </collision>
  </link>
  <joint
    name="A4_Joint"
    type="revolute">
    <origin
      xyz="2.5124E-05 0 0.1621"
      rpy="0 0 0" />
    <parent
      link="A3_Link" />
    <child
      link="A4_Link" />
    <axis
      xyz="0 1 0" />
    <limit
      lower="-2.05"
      upper="2.05"
      effort="36"
      velocity="9.1" />
  </joint>
  <link
    name="A5_Link">
    <inertial>
      <origin
        xyz="-7.5417E-05 -0.0018019 0.037052"
        rpy="0 0 0" />
      <mass
        value="0.30345" />
      <inertia
        ixx="0.00035395"
        ixy="-8.4489E-07"
        ixz="1.0439E-06"
        iyy="0.00038269"
        iyz="1.7802E-06"
        izz="0.00010171" />
    </inertial>
    <visual>
      <origin
        xyz="0 0 0"
        rpy="0 0 0" />
      <geometry>
        <mesh
          filename="meshes/A5_Link.STL" />
      </geometry>
      <material
        name="">
        <color
          rgba="0.75294 0.75294 0.75294 1" />
      </material>
    </visual>
    <collision>
      <origin
        xyz="0 0 0"
        rpy="0 0 0" />
      <geometry>
        <mesh
          filename="meshes/A5_Link.STL" />
      </geometry>
    </collision>
  </link>
  <joint
    name="A5_Joint"
    type="revolute">
    <origin
      xyz="0 0 0.124"
      rpy="0 0 0" />
    <parent
      link="A4_Link" />
    <child
      link="A5_Link" />
    <axis
      xyz="0 0 1" />
    <limit
      lower="-2.69"
      upper="2.69"
      effort="36"
      velocity="9.1" />
  </joint>
  <link
    name="A6_Link">
    <inertial>
      <origin
        xyz="0.0042338 0.0043863 0.032482"
        rpy="0 0 0" />
      <mass
        value="0.34433" />
      <inertia
        ixx="0.0001944"
        ixy="-1.3389E-06"
        ixz="-9.4704E-06"
        iyy="0.00023388"
        iyz="2.8728E-07"
        izz="0.00010146" />
    </inertial>
    <visual>
      <origin
        xyz="0 0 0"
        rpy="0 0 0" />
      <geometry>
        <mesh
          filename="meshes/A6_Link.STL" />
      </geometry>
      <material
        name="">
        <color
          rgba="0.75294 0.75294 0.75294 1" />
      </material>
    </visual>
    <collision>
      <origin
        xyz="0 0 0"
        rpy="0 0 0" />
      <geometry>
        <mesh
          filename="meshes/A6_Link.STL" />
      </geometry>
    </collision>
  </link>
  <joint
    name="A6_Joint"
    type="revolute">
    <origin
      xyz="0 0 0.0881"
      rpy="0 0 0" />
    <parent
      link="A5_Link" />
    <child
      link="A6_Link" />
    <axis
      xyz="0 1 0" />
    <limit
      lower="-1.59"
      upper="1.59"
      effort="18"
      velocity="7.33" />
  </joint>
  <link
    name="A7_Link">
    <inertial>
      <origin
        xyz="-0.0033322 -1.0729E-06 0.020243"
        rpy="0 0 0" />
      <mass
        value="0.14331" />
      <inertia
        ixx="6.9817E-05"
        ixy="-2.7113E-07"
        ixz="3.1827E-08"
        iyy="5.4868E-05"
        iyz="-6.307E-13"
        izz="4.4021E-05" />
    </inertial>
    <visual>
      <origin
        xyz="0 0 0"
        rpy="0 0 0" />
      <geometry>
        <mesh
          filename="meshes/A7_Link.STL" />
      </geometry>
      <material
        name="">
        <color
          rgba="0.75294 0.75294 0.75294 1" />
      </material>
    </visual>
    <collision>
      <origin
        xyz="0 0 0"
        rpy="0 0 0" />
      <geometry>
        <mesh
          filename="meshes/A7_Link.STL" />
      </geometry>
    </collision>
  </link>
  <joint
    name="A7_Joint"
    type="revolute">
    <origin
      xyz="0 0 0.0655"
      rpy="0 0 0" />
    <parent
      link="A6_Link" />
    <child
      link="A7_Link" />
    <axis
      xyz="1 0 0" />
    <limit
      lower="-1.59"
      upper="1.59"
      effort="18"
      velocity="7.33" />
  </joint>
  <link
    name="A8_Link">
    <inertial>
      <origin
        xyz="1.0381E-10 5.2909E-11 -0.0005"
        rpy="0 0 0" />
      <mass
        value="6.0515E-05" />
      <inertia
        ixx="8.496E-09"
        ixy="1.8809E-22"
        ixz="-1.7618E-15"
        iyy="8.496E-09"
        iyz="-9.0596E-16"
        izz="1.6982E-08" />
    </inertial>
    <visual>
      <origin
        xyz="0 0 0"
        rpy="0 0 0" />
      <geometry>
        <mesh
          filename="meshes/A8_Link.STL" />
      </geometry>
      <material
        name="">
        <color
          rgba="0.78039 0.97255 0.95686 1" />
      </material>
    </visual>
    <collision>
      <origin
        xyz="0 0 0"
        rpy="0 0 0" />
      <geometry>
        <mesh
          filename="meshes/A8_Link.STL" />
      </geometry>
    </collision>
  </link>
  <joint
    name="A8_Joint"
    type="fixed">
    <origin
      xyz="0 0 0.0455"
      rpy="0 0 0" />
    <parent
      link="A7_Link" />
    <child
      link="A8_Link" />
    <axis
      xyz="0 0 0" />
  </joint>
</robot>